# Own-Exception-handling-in-Python
Own exception in Python
